Traceback (most recent call last):
  File "/usr/local/pyenv/versions/3.9.8/lib/python3.9/site-packages/jupyter_cache/executors/utils.py", line 51, in single_nb_execution
    executenb(
  File "/usr/local/pyenv/versions/3.9.8/lib/python3.9/site-packages/nbclient/client.py", line 1204, in execute
    return NotebookClient(nb=nb, resources=resources, km=km, **kwargs).execute()
  File "/usr/local/pyenv/versions/3.9.8/lib/python3.9/site-packages/nbclient/util.py", line 84, in wrapped
    return just_run(coro(*args, **kwargs))
  File "/usr/local/pyenv/versions/3.9.8/lib/python3.9/site-packages/nbclient/util.py", line 62, in just_run
    return loop.run_until_complete(coro)
  File "/usr/local/pyenv/versions/3.9.8/lib/python3.9/asyncio/base_events.py", line 642, in run_until_complete
    return future.result()
  File "/usr/local/pyenv/versions/3.9.8/lib/python3.9/site-packages/nbclient/client.py", line 663, in async_execute
    await self.async_execute_cell(
  File "/usr/local/pyenv/versions/3.9.8/lib/python3.9/site-packages/nbclient/client.py", line 965, in async_execute_cell
    await self._check_raise_for_error(cell, cell_index, exec_reply)
  File "/usr/local/pyenv/versions/3.9.8/lib/python3.9/site-packages/nbclient/client.py", line 862, in _check_raise_for_error
    raise CellExecutionError.from_cell_and_msg(cell, exec_reply_content)
nbclient.exceptions.CellExecutionError: An error occurred while executing the following cell:
------------------
# Read it
with xr.open_dataset(os.path.join(WORKING_DIR, 'run_output.nc')) as ds:
    ds = ds.load()
df_stats = pd.read_csv(os.path.join(WORKING_DIR, 'glacier_statistics.csv'), index_col=0)
------------------

[0;31m---------------------------------------------------------------------------[0m
[0;31mNameError[0m                                 Traceback (most recent call last)
[0;32m/tmp/ipykernel_834/2522121547.py[0m in [0;36m<module>[0;34m[0m
[1;32m      1[0m [0;31m# Read it[0m[0;34m[0m[0;34m[0m[0m
[0;32m----> 2[0;31m [0;32mwith[0m [0mxr[0m[0;34m.[0m[0mopen_dataset[0m[0;34m([0m[0mos[0m[0;34m.[0m[0mpath[0m[0;34m.[0m[0mjoin[0m[0;34m([0m[0mWORKING_DIR[0m[0;34m,[0m [0;34m'run_output.nc'[0m[0;34m)[0m[0;34m)[0m [0;32mas[0m [0mds[0m[0;34m:[0m[0;34m[0m[0;34m[0m[0m
[0m[1;32m      3[0m     [0mds[0m [0;34m=[0m [0mds[0m[0;34m.[0m[0mload[0m[0;34m([0m[0;34m)[0m[0;34m[0m[0;34m[0m[0m
[1;32m      4[0m [0mdf_stats[0m [0;34m=[0m [0mpd[0m[0;34m.[0m[0mread_csv[0m[0;34m([0m[0mos[0m[0;34m.[0m[0mpath[0m[0;34m.[0m[0mjoin[0m[0;34m([0m[0mWORKING_DIR[0m[0;34m,[0m [0;34m'glacier_statistics.csv'[0m[0;34m)[0m[0;34m,[0m [0mindex_col[0m[0;34m=[0m[0;36m0[0m[0;34m)[0m[0;34m[0m[0;34m[0m[0m

[0;31mNameError[0m: name 'WORKING_DIR' is not defined
NameError: name 'WORKING_DIR' is not defined

