Traceback (most recent call last):
  File "/usr/local/pyenv/versions/3.10.10/lib/python3.10/site-packages/jupyter_cache/executors/utils.py", line 51, in single_nb_execution
    executenb(
  File "/usr/local/pyenv/versions/3.10.10/lib/python3.10/site-packages/nbclient/client.py", line 1204, in execute
    return NotebookClient(nb=nb, resources=resources, km=km, **kwargs).execute()
  File "/usr/local/pyenv/versions/3.10.10/lib/python3.10/site-packages/nbclient/util.py", line 84, in wrapped
    return just_run(coro(*args, **kwargs))
  File "/usr/local/pyenv/versions/3.10.10/lib/python3.10/site-packages/nbclient/util.py", line 62, in just_run
    return loop.run_until_complete(coro)
  File "/usr/local/pyenv/versions/3.10.10/lib/python3.10/asyncio/base_events.py", line 649, in run_until_complete
    return future.result()
  File "/usr/local/pyenv/versions/3.10.10/lib/python3.10/site-packages/nbclient/client.py", line 663, in async_execute
    await self.async_execute_cell(
  File "/usr/local/pyenv/versions/3.10.10/lib/python3.10/site-packages/nbclient/client.py", line 965, in async_execute_cell
    await self._check_raise_for_error(cell, cell_index, exec_reply)
  File "/usr/local/pyenv/versions/3.10.10/lib/python3.10/site-packages/nbclient/client.py", line 862, in _check_raise_for_error
    raise CellExecutionError.from_cell_and_msg(cell, exec_reply_content)
nbclient.exceptions.CellExecutionError: An error occurred while executing the following cell:
------------------
# We use a recent gdir setting, calibated on a glacier per glacier basis
base_url = 'https://cluster.klima.uni-bremen.de/~oggm/gdirs/oggm_v1.6/L3-L5_files/ERA5/elev_bands/qc0/pcp1.6/match_geod_pergla/'

# These parameters correspond to the settings of the base url
cfg.PARAMS['prcp_scaling_factor'] = 1.6
cfg.PARAMS['climate_qc_months'] = 0
cfg.PARAMS['hydro_month_nh'] = 1
cfg.PARAMS['hydro_month_sh'] = 1
cfg.PARAMS['max_mu_star'] = 600
------------------

[0;31m---------------------------------------------------------------------------[0m
[0;31mInvalidParamsError[0m                        Traceback (most recent call last)
Cell [0;32mIn[7], line 5[0m
[1;32m      2[0m base_url [38;5;241m=[39m [38;5;124m'[39m[38;5;124mhttps://cluster.klima.uni-bremen.de/~oggm/gdirs/oggm_v1.6/L3-L5_files/ERA5/elev_bands/qc0/pcp1.6/match_geod_pergla/[39m[38;5;124m'[39m
[1;32m      4[0m [38;5;66;03m# These parameters correspond to the settings of the base url[39;00m
[0;32m----> 5[0m [43mcfg[49m[38;5;241;43m.[39;49m[43mPARAMS[49m[43m[[49m[38;5;124;43m'[39;49m[38;5;124;43mprcp_scaling_factor[39;49m[38;5;124;43m'[39;49m[43m][49m [38;5;241m=[39m [38;5;241m1.6[39m
[1;32m      6[0m cfg[38;5;241m.[39mPARAMS[[38;5;124m'[39m[38;5;124mclimate_qc_months[39m[38;5;124m'[39m] [38;5;241m=[39m [38;5;241m0[39m
[1;32m      7[0m cfg[38;5;241m.[39mPARAMS[[38;5;124m'[39m[38;5;124mhydro_month_nh[39m[38;5;124m'[39m] [38;5;241m=[39m [38;5;241m1[39m

File [0;32m/usr/local/pyenv/versions/3.10.10/lib/python3.10/site-packages/oggm/cfg.py:119[0m, in [0;36mParamsLoggingDict.__setitem__[0;34m(self, key, value)[0m
[1;32m    117[0m [38;5;28;01mif[39;00m [38;5;28mself[39m[38;5;241m.[39mdo_log:
[1;32m    118[0m     [38;5;28;01mif[39;00m key [38;5;129;01mnot[39;00m [38;5;129;01min[39;00m [38;5;28mself[39m:
[0;32m--> 119[0m         [38;5;28;01mraise[39;00m InvalidParamsError([38;5;124mf[39m[38;5;124m'[39m[38;5;124mParameter `[39m[38;5;132;01m{[39;00mkey[38;5;132;01m}[39;00m[38;5;124m` not in PARAMS[39m[38;5;124m'[39m)
[1;32m    120[0m     [38;5;28mself[39m[38;5;241m.[39m_log_param_change(key, value)
[1;32m    121[0m ResettingOrderedDict[38;5;241m.[39m[38;5;21m__setitem__[39m([38;5;28mself[39m, key, value)

[0;31mInvalidParamsError[0m: Parameter `prcp_scaling_factor` not in PARAMS
InvalidParamsError: Parameter `prcp_scaling_factor` not in PARAMS

