Traceback (most recent call last):
  File "/usr/local/pyenv/versions/3.8.12/lib/python3.8/site-packages/jupyter_cache/executors/utils.py", line 51, in single_nb_execution
    executenb(
  File "/usr/local/pyenv/versions/3.8.12/lib/python3.8/site-packages/nbclient/client.py", line 1117, in execute
    return NotebookClient(nb=nb, resources=resources, km=km, **kwargs).execute()
  File "/usr/local/pyenv/versions/3.8.12/lib/python3.8/site-packages/nbclient/util.py", line 78, in wrapped
    return just_run(coro(*args, **kwargs))
  File "/usr/local/pyenv/versions/3.8.12/lib/python3.8/site-packages/nbclient/util.py", line 57, in just_run
    return loop.run_until_complete(coro)
  File "/usr/local/pyenv/versions/3.8.12/lib/python3.8/asyncio/base_events.py", line 616, in run_until_complete
    return future.result()
  File "/usr/local/pyenv/versions/3.8.12/lib/python3.8/site-packages/nbclient/client.py", line 558, in async_execute
    await self.async_execute_cell(
  File "/usr/local/pyenv/versions/3.8.12/lib/python3.8/site-packages/nbclient/client.py", line 862, in async_execute_cell
    self._check_raise_for_error(cell, exec_reply)
  File "/usr/local/pyenv/versions/3.8.12/lib/python3.8/site-packages/nbclient/client.py", line 765, in _check_raise_for_error
    raise CellExecutionError.from_cell_and_msg(cell, exec_reply_content)
nbclient.exceptions.CellExecutionError: An error occurred while executing the following cell:
------------------
f, ax = plt.subplots(figsize=(9, 9))
smap.set_data(ds.consensus_ice_thickness)
smap.set_cmap('Blues')
smap.plot(ax=ax)
smap.append_colorbar(ax=ax, label='ice thickness (m)');
------------------

[0;31m---------------------------------------------------------------------------[0m
[0;31mNameError[0m                                 Traceback (most recent call last)
[0;32m/tmp/ipykernel_1035/2144386927.py[0m in [0;36m<module>[0;34m[0m
[0;32m----> 1[0;31m [0mf[0m[0;34m,[0m [0max[0m [0;34m=[0m [0mplt[0m[0;34m.[0m[0msubplots[0m[0;34m([0m[0mfigsize[0m[0;34m=[0m[0;34m([0m[0;36m9[0m[0;34m,[0m [0;36m9[0m[0;34m)[0m[0;34m)[0m[0;34m[0m[0;34m[0m[0m
[0m[1;32m      2[0m [0msmap[0m[0;34m.[0m[0mset_data[0m[0;34m([0m[0mds[0m[0;34m.[0m[0mconsensus_ice_thickness[0m[0;34m)[0m[0;34m[0m[0;34m[0m[0m
[1;32m      3[0m [0msmap[0m[0;34m.[0m[0mset_cmap[0m[0;34m([0m[0;34m'Blues'[0m[0;34m)[0m[0;34m[0m[0;34m[0m[0m
[1;32m      4[0m [0msmap[0m[0;34m.[0m[0mplot[0m[0;34m([0m[0max[0m[0;34m=[0m[0max[0m[0;34m)[0m[0;34m[0m[0;34m[0m[0m
[1;32m      5[0m [0msmap[0m[0;34m.[0m[0mappend_colorbar[0m[0;34m([0m[0max[0m[0;34m=[0m[0max[0m[0;34m,[0m [0mlabel[0m[0;34m=[0m[0;34m'ice thickness (m)'[0m[0;34m)[0m[0;34m;[0m[0;34m[0m[0;34m[0m[0m

[0;31mNameError[0m: name 'plt' is not defined
NameError: name 'plt' is not defined

