Traceback (most recent call last):
  File "/usr/local/pyenv/versions/3.10.10/lib/python3.10/site-packages/jupyter_cache/executors/utils.py", line 51, in single_nb_execution
    executenb(
  File "/usr/local/pyenv/versions/3.10.10/lib/python3.10/site-packages/nbclient/client.py", line 1204, in execute
    return NotebookClient(nb=nb, resources=resources, km=km, **kwargs).execute()
  File "/usr/local/pyenv/versions/3.10.10/lib/python3.10/site-packages/nbclient/util.py", line 84, in wrapped
    return just_run(coro(*args, **kwargs))
  File "/usr/local/pyenv/versions/3.10.10/lib/python3.10/site-packages/nbclient/util.py", line 62, in just_run
    return loop.run_until_complete(coro)
  File "/usr/local/pyenv/versions/3.10.10/lib/python3.10/asyncio/base_events.py", line 649, in run_until_complete
    return future.result()
  File "/usr/local/pyenv/versions/3.10.10/lib/python3.10/site-packages/nbclient/client.py", line 663, in async_execute
    await self.async_execute_cell(
  File "/usr/local/pyenv/versions/3.10.10/lib/python3.10/site-packages/nbclient/client.py", line 965, in async_execute_cell
    await self._check_raise_for_error(cell, cell_index, exec_reply)
  File "/usr/local/pyenv/versions/3.10.10/lib/python3.10/site-packages/nbclient/client.py", line 862, in _check_raise_for_error
    raise CellExecutionError.from_cell_and_msg(cell, exec_reply_content)
nbclient.exceptions.CellExecutionError: An error occurred while executing the following cell:
------------------
# Since we overwrote the inversion flowlines we have to do stuff again
tasks.mb_calibration_from_geodetic_mb(gdir,
                                      informed_threestep=True,
                                      overwrite_gdir=True)
tasks.apparent_mb_from_any_mb(gdir)
tasks.prepare_for_inversion(gdir, add_debug_var=True)
tasks.mass_conservation_inversion(gdir)
tasks.compute_velocities(gdir)
------------------

[0;31m---------------------------------------------------------------------------[0m
[0;31mTypeError[0m                                 Traceback (most recent call last)
Cell [0;32mIn[38], line 6[0m
[1;32m      2[0m tasks[38;5;241m.[39mmb_calibration_from_geodetic_mb(gdir,
[1;32m      3[0m                                       informed_threestep[38;5;241m=[39m[38;5;28;01mTrue[39;00m,
[1;32m      4[0m                                       overwrite_gdir[38;5;241m=[39m[38;5;28;01mTrue[39;00m)
[1;32m      5[0m tasks[38;5;241m.[39mapparent_mb_from_any_mb(gdir)
[0;32m----> 6[0m [43mtasks[49m[38;5;241;43m.[39;49m[43mprepare_for_inversion[49m[43m([49m[43mgdir[49m[43m,[49m[43m [49m[43madd_debug_var[49m[38;5;241;43m=[39;49m[38;5;28;43;01mTrue[39;49;00m[43m)[49m
[1;32m      7[0m tasks[38;5;241m.[39mmass_conservation_inversion(gdir)
[1;32m      8[0m tasks[38;5;241m.[39mcompute_velocities(gdir)

File [0;32m/usr/local/pyenv/versions/3.10.10/lib/python3.10/site-packages/oggm/utils/_workflow.py:491[0m, in [0;36mentity_task.__call__.<locals>._entity_task[0;34m(gdir, reset, print_log, return_value, continue_on_error, add_to_log_file, **kwargs)[0m
[1;32m    489[0m     signal[38;5;241m.[39malarm(cfg[38;5;241m.[39mPARAMS[[38;5;124m'[39m[38;5;124mtask_timeout[39m[38;5;124m'[39m])
[1;32m    490[0m ex_t [38;5;241m=[39m time[38;5;241m.[39mtime()
[0;32m--> 491[0m out [38;5;241m=[39m [43mtask_func[49m[43m([49m[43mgdir[49m[43m,[49m[43m [49m[38;5;241;43m*[39;49m[38;5;241;43m*[39;49m[43mkwargs[49m[43m)[49m
[1;32m    492[0m ex_t [38;5;241m=[39m time[38;5;241m.[39mtime() [38;5;241m-[39m ex_t
[1;32m    493[0m [38;5;28;01mif[39;00m cfg[38;5;241m.[39mPARAMS[[38;5;124m'[39m[38;5;124mtask_timeout[39m[38;5;124m'[39m] [38;5;241m>[39m [38;5;241m0[39m:

[0;31mTypeError[0m: prepare_for_inversion() got an unexpected keyword argument 'add_debug_var'
TypeError: prepare_for_inversion() got an unexpected keyword argument 'add_debug_var'

