Traceback (most recent call last):
  File "/usr/local/pyenv/versions/3.10.10/lib/python3.10/site-packages/jupyter_cache/executors/utils.py", line 51, in single_nb_execution
    executenb(
  File "/usr/local/pyenv/versions/3.10.10/lib/python3.10/site-packages/nbclient/client.py", line 1204, in execute
    return NotebookClient(nb=nb, resources=resources, km=km, **kwargs).execute()
  File "/usr/local/pyenv/versions/3.10.10/lib/python3.10/site-packages/nbclient/util.py", line 84, in wrapped
    return just_run(coro(*args, **kwargs))
  File "/usr/local/pyenv/versions/3.10.10/lib/python3.10/site-packages/nbclient/util.py", line 62, in just_run
    return loop.run_until_complete(coro)
  File "/usr/local/pyenv/versions/3.10.10/lib/python3.10/asyncio/base_events.py", line 649, in run_until_complete
    return future.result()
  File "/usr/local/pyenv/versions/3.10.10/lib/python3.10/site-packages/nbclient/client.py", line 663, in async_execute
    await self.async_execute_cell(
  File "/usr/local/pyenv/versions/3.10.10/lib/python3.10/site-packages/nbclient/client.py", line 965, in async_execute_cell
    await self._check_raise_for_error(cell, cell_index, exec_reply)
  File "/usr/local/pyenv/versions/3.10.10/lib/python3.10/site-packages/nbclient/client.py", line 862, in _check_raise_for_error
    raise CellExecutionError.from_cell_and_msg(cell, exec_reply_content)
nbclient.exceptions.CellExecutionError: An error occurred while executing the following cell:
------------------
import numpy as np
import pandas as pd
import geopandas as gpd
import matplotlib.pyplot as plt
import oggm
from oggm import cfg, utils, workflow, tasks, graphics
from oggm.core.inversion import find_inversion_calving, calving_flux_from_depth
------------------

[0;31m---------------------------------------------------------------------------[0m
[0;31mImportError[0m                               Traceback (most recent call last)
Cell [0;32mIn[2], line 7[0m
[1;32m      5[0m [38;5;28;01mimport[39;00m [38;5;21;01moggm[39;00m
[1;32m      6[0m [38;5;28;01mfrom[39;00m [38;5;21;01moggm[39;00m [38;5;28;01mimport[39;00m cfg, utils, workflow, tasks, graphics
[0;32m----> 7[0m [38;5;28;01mfrom[39;00m [38;5;21;01moggm[39;00m[38;5;21;01m.[39;00m[38;5;21;01mcore[39;00m[38;5;21;01m.[39;00m[38;5;21;01minversion[39;00m [38;5;28;01mimport[39;00m find_inversion_calving, calving_flux_from_depth

[0;31mImportError[0m: cannot import name 'find_inversion_calving' from 'oggm.core.inversion' (/usr/local/pyenv/versions/3.10.10/lib/python3.10/site-packages/oggm/core/inversion.py)
ImportError: cannot import name 'find_inversion_calving' from 'oggm.core.inversion' (/usr/local/pyenv/versions/3.10.10/lib/python3.10/site-packages/oggm/core/inversion.py)

