Traceback (most recent call last):
  File "/usr/local/pyenv/versions/3.10.10/lib/python3.10/site-packages/jupyter_cache/executors/utils.py", line 51, in single_nb_execution
    executenb(
  File "/usr/local/pyenv/versions/3.10.10/lib/python3.10/site-packages/nbclient/client.py", line 1204, in execute
    return NotebookClient(nb=nb, resources=resources, km=km, **kwargs).execute()
  File "/usr/local/pyenv/versions/3.10.10/lib/python3.10/site-packages/nbclient/util.py", line 84, in wrapped
    return just_run(coro(*args, **kwargs))
  File "/usr/local/pyenv/versions/3.10.10/lib/python3.10/site-packages/nbclient/util.py", line 62, in just_run
    return loop.run_until_complete(coro)
  File "/usr/local/pyenv/versions/3.10.10/lib/python3.10/asyncio/base_events.py", line 649, in run_until_complete
    return future.result()
  File "/usr/local/pyenv/versions/3.10.10/lib/python3.10/site-packages/nbclient/client.py", line 663, in async_execute
    await self.async_execute_cell(
  File "/usr/local/pyenv/versions/3.10.10/lib/python3.10/site-packages/nbclient/client.py", line 965, in async_execute_cell
    await self._check_raise_for_error(cell, cell_index, exec_reply)
  File "/usr/local/pyenv/versions/3.10.10/lib/python3.10/site-packages/nbclient/client.py", line 862, in _check_raise_for_error
    raise CellExecutionError.from_cell_and_msg(cell, exec_reply_content)
nbclient.exceptions.CellExecutionError: An error occurred while executing the following cell:
------------------
# Libs
import geopandas as gpd

# Locals
import oggm.cfg as cfg
from oggm import utils, workflow, tasks, graphics

# Initialize OGGM and set up the default run parameters
cfg.initialize(logging_level='WARNING')
rgi_region = '11'  # Region Central Europe

# Local working directory (where OGGM will write its output)
WORKING_DIR = utils.gettempdir('OGGM_Inversion')
cfg.PATHS['working_dir'] = WORKING_DIR

# This is useful here
cfg.PARAMS['use_multiprocessing'] = True

# RGI file
path = utils.get_rgi_region_file(rgi_region)
rgidf = gpd.read_file(path)

# Select the glaciers in the Pyrenees
rgidf = rgidf.loc[rgidf['O2Region'] == '2']

# Sort for more efficient parallel computing
rgidf = rgidf.sort_values('Area', ascending=False)

# Go - get the pre-processed glacier directories
# We start at level 3, because we need all data for the inversion
gdirs = workflow.init_glacier_directories(rgidf, from_prepro_level=3, prepro_border=10)

# Because of recent changes in OGGM not yet available in the preprocessed directories, 
# we re-run this task:
workflow.execute_entity_task(tasks.prepare_for_inversion, gdirs)

# Default parameters
# Deformation: from Cuffey and Patterson 2010
glen_a = 2.4e-24
# Sliding: from Oerlemans 1997
fs = 5.7e-20
------------------

[0;31m---------------------------------------------------------------------------[0m
[0;31mInvalidParamsError[0m                        Traceback (most recent call last)
Cell [0;32mIn[1], line 31[0m
[1;32m     27[0m rgidf [38;5;241m=[39m rgidf[38;5;241m.[39msort_values([38;5;124m'[39m[38;5;124mArea[39m[38;5;124m'[39m, ascending[38;5;241m=[39m[38;5;28;01mFalse[39;00m)
[1;32m     29[0m [38;5;66;03m# Go - get the pre-processed glacier directories[39;00m
[1;32m     30[0m [38;5;66;03m# We start at level 3, because we need all data for the inversion[39;00m
[0;32m---> 31[0m gdirs [38;5;241m=[39m [43mworkflow[49m[38;5;241;43m.[39;49m[43minit_glacier_directories[49m[43m([49m[43mrgidf[49m[43m,[49m[43m [49m[43mfrom_prepro_level[49m[38;5;241;43m=[39;49m[38;5;241;43m3[39;49m[43m,[49m[43m [49m[43mprepro_border[49m[38;5;241;43m=[39;49m[38;5;241;43m10[39;49m[43m)[49m
[1;32m     33[0m [38;5;66;03m# Because of recent changes in OGGM not yet available in the preprocessed directories, [39;00m
[1;32m     34[0m [38;5;66;03m# we re-run this task:[39;00m
[1;32m     35[0m workflow[38;5;241m.[39mexecute_entity_task(tasks[38;5;241m.[39mprepare_for_inversion, gdirs)

File [0;32m/usr/local/pyenv/versions/3.10.10/lib/python3.10/site-packages/oggm/workflow.py:364[0m, in [0;36minit_glacier_directories[0;34m(rgidf, reset, force, from_prepro_level, prepro_border, prepro_rgi_version, prepro_base_url, from_tar, delete_tar)[0m
[1;32m    361[0m     reset [38;5;241m=[39m utils[38;5;241m.[39mquery_yes_no([38;5;124m'[39m[38;5;124mDelete all glacier directories?[39m[38;5;124m'[39m)
[1;32m    363[0m [38;5;28;01mif[39;00m from_prepro_level:
[0;32m--> 364[0m     url [38;5;241m=[39m [43mutils[49m[38;5;241;43m.[39;49m[43mget_prepro_base_url[49m[43m([49m[43mbase_url[49m[38;5;241;43m=[39;49m[43mprepro_base_url[49m[43m,[49m
[1;32m    365[0m [43m                                    [49m[43mborder[49m[38;5;241;43m=[39;49m[43mprepro_border[49m[43m,[49m
[1;32m    366[0m [43m                                    [49m[43mprepro_level[49m[38;5;241;43m=[39;49m[43mfrom_prepro_level[49m[43m,[49m
[1;32m    367[0m [43m                                    [49m[43mrgi_version[49m[38;5;241;43m=[39;49m[43mprepro_rgi_version[49m[43m)[49m
[1;32m    368[0m     [38;5;28;01mif[39;00m cfg[38;5;241m.[39mPARAMS[[38;5;124m'[39m[38;5;124mhas_internet[39m[38;5;124m'[39m] [38;5;129;01mand[39;00m [38;5;129;01mnot[39;00m utils[38;5;241m.[39murl_exists(url):
[1;32m    369[0m         [38;5;28;01mraise[39;00m InvalidParamsError([38;5;124m"[39m[38;5;124mbase url seems unreachable with these [39m[38;5;124m"[39m
[1;32m    370[0m                                  [38;5;124m"[39m[38;5;124mparameters: [39m[38;5;132;01m{}[39;00m[38;5;124m"[39m[38;5;241m.[39mformat(url))

File [0;32m/usr/local/pyenv/versions/3.10.10/lib/python3.10/site-packages/oggm/utils/_downloads.py:1278[0m, in [0;36mget_prepro_base_url[0;34m(base_url, rgi_version, border, prepro_level)[0m
[1;32m   1275[0m [38;5;250m[39m[38;5;124;03m"""Extended base url where to find the desired gdirs."""[39;00m
[1;32m   1277[0m [38;5;28;01mif[39;00m base_url [38;5;129;01mis[39;00m [38;5;28;01mNone[39;00m:
[0;32m-> 1278[0m     [38;5;28;01mraise[39;00m InvalidParamsError([38;5;124m'[39m[38;5;124mStarting with v1.6, users now have to [39m[38;5;124m'[39m
[1;32m   1279[0m                              [38;5;124m'[39m[38;5;124mexplicitly indicate the url they want [39m[38;5;124m'[39m
[1;32m   1280[0m                              [38;5;124m'[39m[38;5;124mto start from.[39m[38;5;124m'[39m)
[1;32m   1282[0m [38;5;28;01mif[39;00m [38;5;129;01mnot[39;00m base_url[38;5;241m.[39mendswith([38;5;124m'[39m[38;5;124m/[39m[38;5;124m'[39m):
[1;32m   1283[0m     base_url [38;5;241m+[39m[38;5;241m=[39m [38;5;124m'[39m[38;5;124m/[39m[38;5;124m'[39m

[0;31mInvalidParamsError[0m: Starting with v1.6, users now have to explicitly indicate the url they want to start from.
InvalidParamsError: Starting with v1.6, users now have to explicitly indicate the url they want to start from.

