Traceback (most recent call last):
  File "/usr/local/pyenv/versions/3.10.10/lib/python3.10/site-packages/jupyter_cache/executors/utils.py", line 51, in single_nb_execution
    executenb(
  File "/usr/local/pyenv/versions/3.10.10/lib/python3.10/site-packages/nbclient/client.py", line 1204, in execute
    return NotebookClient(nb=nb, resources=resources, km=km, **kwargs).execute()
  File "/usr/local/pyenv/versions/3.10.10/lib/python3.10/site-packages/nbclient/util.py", line 84, in wrapped
    return just_run(coro(*args, **kwargs))
  File "/usr/local/pyenv/versions/3.10.10/lib/python3.10/site-packages/nbclient/util.py", line 62, in just_run
    return loop.run_until_complete(coro)
  File "/usr/local/pyenv/versions/3.10.10/lib/python3.10/asyncio/base_events.py", line 649, in run_until_complete
    return future.result()
  File "/usr/local/pyenv/versions/3.10.10/lib/python3.10/site-packages/nbclient/client.py", line 663, in async_execute
    await self.async_execute_cell(
  File "/usr/local/pyenv/versions/3.10.10/lib/python3.10/site-packages/nbclient/client.py", line 965, in async_execute_cell
    await self._check_raise_for_error(cell, cell_index, exec_reply)
  File "/usr/local/pyenv/versions/3.10.10/lib/python3.10/site-packages/nbclient/client.py", line 862, in _check_raise_for_error
    raise CellExecutionError.from_cell_and_msg(cell, exec_reply_content)
nbclient.exceptions.CellExecutionError: An error occurred while executing the following cell:
------------------
"% area errors all sources for ERA5 is {:.2f}% compared to CRU ({:.2f}%)".format(df_era5.loc[~df_era5['error_task'].isnull()].rgi_area_km2.sum() / df_era5.rgi_area_km2.sum() * 100,
                                                                              df.loc[~df['error_task'].isnull()].rgi_area_km2.sum() / df.rgi_area_km2.sum() * 100)
------------------

[0;31m---------------------------------------------------------------------------[0m
[0;31mNameError[0m                                 Traceback (most recent call last)
Cell [0;32mIn[11], line 1[0m
[0;32m----> 1[0m [38;5;124m"[39m[38;5;132;01m% a[39;00m[38;5;124mrea errors all sources for ERA5 is [39m[38;5;132;01m{:.2f}[39;00m[38;5;132;01m% c[39;00m[38;5;124mompared to CRU ([39m[38;5;132;01m{:.2f}[39;00m[38;5;124m%[39m[38;5;124m)[39m[38;5;124m"[39m[38;5;241m.[39mformat([43mdf_era5[49m[38;5;241m.[39mloc[[38;5;241m~[39mdf_era5[[38;5;124m'[39m[38;5;124merror_task[39m[38;5;124m'[39m][38;5;241m.[39misnull()][38;5;241m.[39mrgi_area_km2[38;5;241m.[39msum() [38;5;241m/[39m df_era5[38;5;241m.[39mrgi_area_km2[38;5;241m.[39msum() [38;5;241m*[39m [38;5;241m100[39m,
[1;32m      2[0m                                                                               df[38;5;241m.[39mloc[[38;5;241m~[39mdf[[38;5;124m'[39m[38;5;124merror_task[39m[38;5;124m'[39m][38;5;241m.[39misnull()][38;5;241m.[39mrgi_area_km2[38;5;241m.[39msum() [38;5;241m/[39m df[38;5;241m.[39mrgi_area_km2[38;5;241m.[39msum() [38;5;241m*[39m [38;5;241m100[39m)

[0;31mNameError[0m: name 'df_era5' is not defined
NameError: name 'df_era5' is not defined

