Traceback (most recent call last):
  File "/usr/local/pyenv/versions/3.10.10/lib/python3.10/site-packages/jupyter_cache/executors/utils.py", line 51, in single_nb_execution
    executenb(
  File "/usr/local/pyenv/versions/3.10.10/lib/python3.10/site-packages/nbclient/client.py", line 1204, in execute
    return NotebookClient(nb=nb, resources=resources, km=km, **kwargs).execute()
  File "/usr/local/pyenv/versions/3.10.10/lib/python3.10/site-packages/nbclient/util.py", line 84, in wrapped
    return just_run(coro(*args, **kwargs))
  File "/usr/local/pyenv/versions/3.10.10/lib/python3.10/site-packages/nbclient/util.py", line 62, in just_run
    return loop.run_until_complete(coro)
  File "/usr/local/pyenv/versions/3.10.10/lib/python3.10/asyncio/base_events.py", line 649, in run_until_complete
    return future.result()
  File "/usr/local/pyenv/versions/3.10.10/lib/python3.10/site-packages/nbclient/client.py", line 663, in async_execute
    await self.async_execute_cell(
  File "/usr/local/pyenv/versions/3.10.10/lib/python3.10/site-packages/nbclient/client.py", line 965, in async_execute_cell
    await self._check_raise_for_error(cell, cell_index, exec_reply)
  File "/usr/local/pyenv/versions/3.10.10/lib/python3.10/site-packages/nbclient/client.py", line 862, in _check_raise_for_error
    raise CellExecutionError.from_cell_and_msg(cell, exec_reply_content)
nbclient.exceptions.CellExecutionError: An error occurred while executing the following cell:
------------------
from oggm import tasks

# run the compute_inversion_velocities task on all gdirs
workflow.execute_entity_task(tasks.compute_inversion_velocities, gdirs);
------------------

[0;31m---------------------------------------------------------------------------[0m
[0;31mAttributeError[0m                            Traceback (most recent call last)
Cell [0;32mIn[17], line 4[0m
[1;32m      1[0m [38;5;28;01mfrom[39;00m [38;5;21;01moggm[39;00m [38;5;28;01mimport[39;00m tasks
[1;32m      3[0m [38;5;66;03m# run the compute_inversion_velocities task on all gdirs[39;00m
[0;32m----> 4[0m workflow[38;5;241m.[39mexecute_entity_task([43mtasks[49m[38;5;241;43m.[39;49m[43mcompute_inversion_velocities[49m, gdirs);

[0;31mAttributeError[0m: module 'oggm.tasks' has no attribute 'compute_inversion_velocities'
AttributeError: module 'oggm.tasks' has no attribute 'compute_inversion_velocities'

