Traceback (most recent call last):
  File "/usr/local/pyenv/versions/3.10.10/lib/python3.10/site-packages/jupyter_cache/executors/utils.py", line 51, in single_nb_execution
    executenb(
  File "/usr/local/pyenv/versions/3.10.10/lib/python3.10/site-packages/nbclient/client.py", line 1204, in execute
    return NotebookClient(nb=nb, resources=resources, km=km, **kwargs).execute()
  File "/usr/local/pyenv/versions/3.10.10/lib/python3.10/site-packages/nbclient/util.py", line 84, in wrapped
    return just_run(coro(*args, **kwargs))
  File "/usr/local/pyenv/versions/3.10.10/lib/python3.10/site-packages/nbclient/util.py", line 62, in just_run
    return loop.run_until_complete(coro)
  File "/usr/local/pyenv/versions/3.10.10/lib/python3.10/asyncio/base_events.py", line 649, in run_until_complete
    return future.result()
  File "/usr/local/pyenv/versions/3.10.10/lib/python3.10/site-packages/nbclient/client.py", line 663, in async_execute
    await self.async_execute_cell(
  File "/usr/local/pyenv/versions/3.10.10/lib/python3.10/site-packages/nbclient/client.py", line 965, in async_execute_cell
    await self._check_raise_for_error(cell, cell_index, exec_reply)
  File "/usr/local/pyenv/versions/3.10.10/lib/python3.10/site-packages/nbclient/client.py", line 862, in _check_raise_for_error
    raise CellExecutionError.from_cell_and_msg(cell, exec_reply_content)
nbclient.exceptions.CellExecutionError: An error occurred while executing the following cell:
------------------
# this will download several large datasets (3 times a few 100s of MB)
from oggm.shop import millan22
workflow.execute_entity_task(millan22.velocity_to_gdir, gdirs);
------------------

[0;31m---------------------------------------------------------------------------[0m
[0;31mImportError[0m                               Traceback (most recent call last)
Cell [0;32mIn[27], line 2[0m
[1;32m      1[0m [38;5;66;03m# this will download several large datasets (3 times a few 100s of MB)[39;00m
[0;32m----> 2[0m [38;5;28;01mfrom[39;00m [38;5;21;01moggm[39;00m[38;5;21;01m.[39;00m[38;5;21;01mshop[39;00m [38;5;28;01mimport[39;00m millan22
[1;32m      3[0m workflow[38;5;241m.[39mexecute_entity_task(millan22[38;5;241m.[39mvelocity_to_gdir, gdirs);

[0;31mImportError[0m: cannot import name 'millan22' from 'oggm.shop' (/usr/local/pyenv/versions/3.10.10/lib/python3.10/site-packages/oggm/shop/__init__.py)
ImportError: cannot import name 'millan22' from 'oggm.shop' (/usr/local/pyenv/versions/3.10.10/lib/python3.10/site-packages/oggm/shop/__init__.py)

